<?xml version='1.0' encoding='UTF-8'?>
<robot name="ur5">
  <link name="base_link">
    <inertial>
      <origin xyz="0.0 0.0 0.0" rpy="0.0 0.0 0.0"/>
      <mass value="4.0"/>
      <inertia ixx="0.00443333156" ixy="0.0" ixz="0.0" iyy="0.00443333156" iyz="0.0" izz="0.0072"/>
    </inertial>
    <visual>
      <geometry>
        <mesh filename="visual/base.dae"/>
      </geometry>
      <material name="LightGrey"/>
      <origin xyz="0.0 0.0 0.0" rpy="0.0 -0.0 0.0"/>
    </visual>
    <collision>
      <geometry>
        <mesh filename="collision/base.stl"/>
      </geometry>
      <origin xyz="0.0 0.0 0.0" rpy="0.0 -0.0 0.0"/>
    </collision>
  </link>
  <link name="shoulder_link">
    <inertial>
      <origin xyz="0.0 0.0 0.0" rpy="0.0 0.0 0.0"/>
      <mass value="3.7"/>
      <inertia ixx="0.010267495893" ixy="0.0" ixz="0.0" iyy="0.010267495893" iyz="0.0" izz="0.00666"/>
    </inertial>
    <visual>
      <geometry>
        <mesh filename="visual/shoulder.dae"/>
      </geometry>
      <material name="LightGrey"/>
      <origin xyz="0.0 0.0 0.0" rpy="0.0 -0.0 0.0"/>
    </visual>
    <collision>
      <geometry>
        <mesh filename="collision/shoulder.stl"/>
      </geometry>
      <origin xyz="0.0 0.0 0.0" rpy="0.0 -0.0 0.0"/>
    </collision>
  </link>
  <link name="upper_arm_link">
    <inertial>
      <origin xyz="0.0 0.0 0.28" rpy="0.0 0.0 0.0"/>
      <mass value="8.393"/>
      <inertia ixx="0.22689067591" ixy="0.0" ixz="0.0" iyy="0.22689067591" iyz="0.0" izz="0.0151074"/>
    </inertial>
    <visual>
      <geometry>
        <mesh filename="visual/upperarm.dae"/>
      </geometry>
      <material name="LightGrey"/>
      <origin xyz="0.0 0.0 0.0" rpy="0.0 -0.0 0.0"/>
    </visual>
    <collision>
      <geometry>
        <mesh filename="collision/upperarm.stl"/>
      </geometry>
      <origin xyz="0.0 0.0 0.0" rpy="0.0 -0.0 0.0"/>
    </collision>
  </link>
  <link name="forearm_link">
    <inertial>
      <origin xyz="0.0 0.0 0.25" rpy="0.0 0.0 0.0"/>
      <mass value="2.275"/>
      <inertia ixx="0.049443313556" ixy="0.0" ixz="0.0" iyy="0.049443313556" iyz="0.0" izz="0.004095"/>
    </inertial>
    <visual>
      <geometry>
        <mesh filename="visual/forearm.dae"/>
      </geometry>
      <material name="LightGrey"/>
      <origin xyz="0.0 0.0 0.0" rpy="0.0 -0.0 0.0"/>
    </visual>
    <collision>
      <geometry>
        <mesh filename="collision/forearm.stl"/>
      </geometry>
      <origin xyz="0.0 0.0 0.0" rpy="0.0 -0.0 0.0"/>
    </collision>
  </link>
  <link name="wrist_1_link">
    <inertial>
      <origin xyz="0.0 0.0 0.0" rpy="0.0 0.0 0.0"/>
      <mass value="1.219"/>
      <inertia ixx="0.111172755531" ixy="0.0" ixz="0.0" iyy="0.111172755531" iyz="0.0" izz="0.21942"/>
    </inertial>
    <visual>
      <geometry>
        <mesh filename="visual/wrist1.dae"/>
      </geometry>
      <material name="LightGrey"/>
      <origin xyz="0.0 0.0 0.0" rpy="0.0 -0.0 0.0"/>
    </visual>
    <collision>
      <geometry>
        <mesh filename="collision/wrist1.stl"/>
      </geometry>
      <origin xyz="0.0 0.0 0.0" rpy="0.0 -0.0 0.0"/>
    </collision>
  </link>
  <link name="wrist_2_link">
    <inertial>
      <origin xyz="0.0 0.0 0.0" rpy="0.0 0.0 0.0"/>
      <mass value="1.219"/>
      <inertia ixx="0.111172755531" ixy="0.0" ixz="0.0" iyy="0.111172755531" iyz="0.0" izz="0.21942"/>
    </inertial>
    <visual>
      <geometry>
        <mesh filename="visual/wrist2.dae"/>
      </geometry>
      <material name="LightGrey"/>
      <origin xyz="0.0 0.0 0.0" rpy="0.0 -0.0 0.0"/>
    </visual>
    <collision>
      <geometry>
        <mesh filename="collision/wrist2.stl"/>
      </geometry>
      <origin xyz="0.0 0.0 0.0" rpy="0.0 -0.0 0.0"/>
    </collision>
  </link>
  <link name="wrist_3_link">
    <inertial>
      <origin xyz="0.0 0.0 0.0" rpy="0.0 0.0 0.0"/>
      <mass value="0.1879"/>
      <inertia ixx="0.0171364731454" ixy="0.0" ixz="0.0" iyy="0.0171364731454" iyz="0.0" izz="0.033822"/>
    </inertial>
    <visual>
      <geometry>
        <mesh filename="visual/wrist3.dae"/>
      </geometry>
      <material name="LightGrey"/>
      <origin xyz="0.0 0.0 0.0" rpy="0.0 -0.0 0.0"/>
    </visual>
    <collision>
      <geometry>
        <mesh filename="collision/wrist3.stl"/>
      </geometry>
      <origin xyz="0.0 0.0 0.0" rpy="0.0 -0.0 0.0"/>
    </collision>
  </link>
  <link name="ee_link">
    <inertial>
      <origin xyz="0.0 0.0 0.0" rpy="0.0 -0.0 0.0"/>
      <mass value="1.0"/>
      <inertia ixx="1.0" ixy="0.0" ixz="0.0" iyy="1.0" iyz="0.0" izz="1.0"/>
    </inertial>
    <collision>
      <geometry>
        <box size="0.01 0.01 0.01"/>
      </geometry>
      <origin xyz="-0.01 0.0 0.0" rpy="0.0 0.0 0.0"/>
    </collision>
  </link>
  <link name="base">
    <inertial>
      <origin xyz="0.0 0.0 0.0" rpy="0.0 -0.0 0.0"/>
      <mass value="1.0"/>
      <inertia ixx="1.0" ixy="0.0" ixz="0.0" iyy="1.0" iyz="0.0" izz="1.0"/>
    </inertial>
  </link>
  <link name="tool0">
    <inertial>
      <origin xyz="0.0 0.0 0.0" rpy="0.0 -0.0 0.0"/>
      <mass value="1.0"/>
      <inertia ixx="1.0" ixy="0.0" ixz="0.0" iyy="1.0" iyz="0.0" izz="1.0"/>
    </inertial>
  </link>
  <link name="world">
    <inertial>
      <origin xyz="0.0 0.0 0.0" rpy="0.0 -0.0 0.0"/>
      <mass value="1.0"/>
      <inertia ixx="1.0" ixy="0.0" ixz="0.0" iyy="1.0" iyz="0.0" izz="1.0"/>
    </inertial>
  </link>
  <joint name="world_joint" type="fixed">
    <parent link="world"/>
    <child link="base_link"/>
    <axis xyz="1. 0. 0."/>
    <origin xyz="0.0 0.0 0.0" rpy="0.0 0.0 0.0"/>
  </joint>
  <joint name="shoulder_pan_joint" type="revolute">
    <dynamics damping="0.0" friction="0.0"/>
    <limit effort="150.0" velocity="3.15" lower="-6.28318530718" upper="6.28318530718"/>
    <parent link="base_link"/>
    <child link="shoulder_link"/>
    <axis xyz="0. 0. 1."/>
    <origin xyz="0.0 0.0 0.089159" rpy="0.0 0.0 0.0"/>
  </joint>
  <joint name="shoulder_lift_joint" type="revolute">
    <dynamics damping="0.0" friction="0.0"/>
    <limit effort="150.0" velocity="3.15" lower="-6.28318530718" upper="6.28318530718"/>
    <parent link="shoulder_link"/>
    <child link="upper_arm_link"/>
    <axis xyz="0. 1. 0."/>
    <origin xyz="0.0 0.13585 0.0" rpy="0.0 1.5707963267948966 0.0"/>
  </joint>
  <joint name="elbow_joint" type="revolute">
    <dynamics damping="0.0" friction="0.0"/>
    <limit effort="150.0" velocity="3.15" lower="-3.14159265359" upper="3.14159265359"/>
    <parent link="upper_arm_link"/>
    <child link="forearm_link"/>
    <axis xyz="0. 1. 0."/>
    <origin xyz="0.0 -0.1197 0.425" rpy="0.0 0.0 0.0"/>
  </joint>
  <joint name="wrist_1_joint" type="revolute">
    <dynamics damping="0.0" friction="0.0"/>
    <limit effort="28.0" velocity="3.2" lower="-6.28318530718" upper="6.28318530718"/>
    <parent link="forearm_link"/>
    <child link="wrist_1_link"/>
    <axis xyz="0. 1. 0."/>
    <origin xyz="0.0 0.0 0.39225" rpy="0.0 1.5707963267948966 0.0"/>
  </joint>
  <joint name="wrist_2_joint" type="revolute">
    <dynamics damping="0.0" friction="0.0"/>
    <limit effort="28.0" velocity="3.2" lower="-6.28318530718" upper="6.28318530718"/>
    <parent link="wrist_1_link"/>
    <child link="wrist_2_link"/>
    <axis xyz="0. 0. 1."/>
    <origin xyz="0.0 0.093 0.0" rpy="0.0 0.0 0.0"/>
  </joint>
  <joint name="wrist_3_joint" type="revolute">
    <dynamics damping="0.0" friction="0.0"/>
    <limit effort="28.0" velocity="3.2" lower="-6.28318530718" upper="6.28318530718"/>
    <parent link="wrist_2_link"/>
    <child link="wrist_3_link"/>
    <axis xyz="0. 1. 0."/>
    <origin xyz="0.0 0.0 0.09465" rpy="0.0 0.0 0.0"/>
  </joint>
  <joint name="ee_fixed_joint" type="fixed">
    <parent link="wrist_3_link"/>
    <child link="ee_link"/>
    <axis xyz="1. 0. 0."/>
    <origin xyz="0.0 0.0823 0.0" rpy="0.0 0.0 1.57079632679"/>
  </joint>
  <joint name="base_link-base_fixed_joint" type="fixed">
    <parent link="base_link"/>
    <child link="base"/>
    <axis xyz="1. 0. 0."/>
    <origin xyz="0.0 0.0 0.0" rpy="0.0 0.0 3.1415926535895866"/>
  </joint>
  <joint name="wrist_3_link-tool0_fixed_joint" type="fixed">
    <parent link="wrist_3_link"/>
    <child link="tool0"/>
    <axis xyz="1. 0. 0."/>
    <origin xyz="0.0 0.0823 0.0" rpy="-1.57079632679 0.0 0.0"/>
  </joint>
  <transmission name="shoulder_pan_trans">
    <joint name="shoulder_pan_joint">
      <hardwareInterface>hardware_interface/PositionJointInterface</hardwareInterface>
    </joint>
    <actuator name="shoulder_pan_motor">
      <mechanicalReduction>1.0</mechanicalReduction>
    </actuator>
    <type>transmission_interface/SimpleTransmission</type>
  </transmission>
  <transmission name="shoulder_lift_trans">
    <joint name="shoulder_lift_joint">
      <hardwareInterface>hardware_interface/PositionJointInterface</hardwareInterface>
    </joint>
    <actuator name="shoulder_lift_motor">
      <mechanicalReduction>1.0</mechanicalReduction>
    </actuator>
    <type>transmission_interface/SimpleTransmission</type>
  </transmission>
  <transmission name="elbow_trans">
    <joint name="elbow_joint">
      <hardwareInterface>hardware_interface/PositionJointInterface</hardwareInterface>
    </joint>
    <actuator name="elbow_motor">
      <mechanicalReduction>1.0</mechanicalReduction>
    </actuator>
    <type>transmission_interface/SimpleTransmission</type>
  </transmission>
  <transmission name="wrist_1_trans">
    <joint name="wrist_1_joint">
      <hardwareInterface>hardware_interface/PositionJointInterface</hardwareInterface>
    </joint>
    <actuator name="wrist_1_motor">
      <mechanicalReduction>1.0</mechanicalReduction>
    </actuator>
    <type>transmission_interface/SimpleTransmission</type>
  </transmission>
  <transmission name="wrist_2_trans">
    <joint name="wrist_2_joint">
      <hardwareInterface>hardware_interface/PositionJointInterface</hardwareInterface>
    </joint>
    <actuator name="wrist_2_motor">
      <mechanicalReduction>1.0</mechanicalReduction>
    </actuator>
    <type>transmission_interface/SimpleTransmission</type>
  </transmission>
  <transmission name="wrist_3_trans">
    <joint name="wrist_3_joint">
      <hardwareInterface>hardware_interface/PositionJointInterface</hardwareInterface>
    </joint>
    <actuator name="wrist_3_motor">
      <mechanicalReduction>1.0</mechanicalReduction>
    </actuator>
    <type>transmission_interface/SimpleTransmission</type>
  </transmission>
  <material name="LightGrey">
    <color rgba="0.7 0.7 0.7 1. "/>
  </material>
  <gazebo>
    <plugin filename="libgazebo_ros_control.so" name="ros_control">
    </plugin>
  </gazebo>
  <gazebo reference="shoulder_link">
    <selfCollide>true</selfCollide>
  </gazebo>
  <gazebo reference="upper_arm_link">
    <selfCollide>true</selfCollide>
  </gazebo>
  <gazebo reference="forearm_link">
    <selfCollide>true</selfCollide>
  </gazebo>
  <gazebo reference="wrist_1_link">
    <selfCollide>true</selfCollide>
  </gazebo>
  <gazebo reference="wrist_3_link">
    <selfCollide>true</selfCollide>
  </gazebo>
  <gazebo reference="wrist_2_link">
    <selfCollide>true</selfCollide>
  </gazebo>
  <gazebo reference="ee_link">
    <selfCollide>true</selfCollide>
  </gazebo>
</robot>
